Workbook

Sheet Cover
A1: شركة فليكسي للتأجير التمويلي
A4: دراسة الجدوى والنموذج المالي المتكامل - Year 1 to Year 5
B8: نطاق النموذج
B9: قوائم مالية سنوية لخمس سنوات
B10: خطة منح شهرية وربع سنوية
B11: تمويل وسيولة وCAR وLCR وNSFR
B12: NPV وIRR وARR والاسترداد وWACC وPI والتعادل
B13: حساسية وسيناريوهات ومؤشرات مالية
B14: هيكل وظيفي ووظائف رقابية
B17: جميع المبالغ بالجنيه المصري. الافتراضات الصفراء قابلة للتعديل، والمعادلات مترابطة بين القوائم والجداول الرقابية. أي مدخل غير مؤكد موصوف صراحة كافتراض.
B22: Version
B23: Final Submission Version
A24: للاطلاع على فهرس تفصيلي بكل ورقة في هذا الملف وما تعرضه ومنهجيتها، مع رابط مباشر لكل ورقة، انظر ورقة "دليل الملف". / For a detailed guide to every sheet in this file, what it shows, and its methodology, with a direct link to each sheet, see the "دليل الملف" (File Guide) sheet.

Sheet دليل الملف
A1: دليل الملف - كل الأوراق ومحتواها
A3: الترتيب | B3: اسم الورقة | C3: ماذا تعرض ومنهجيتها | D3: Navigation
A4: 1 | B4: Cover | C4: صفحة تعريفية بالشركة ونطاق النموذج - لا حسابات، مقدمة فقط. | D4: =IFERROR(HYPERLINK("#'Cover'!A1","Open →"),"Open →") -> Open →
A5: 2 | B5: Assumptions | C5: يجمع الافتراضات الرئيسية: التكاليف، الأسعار، الآجال، رأس المال، والافتراضات الرقابية. معظم محركات النموذج ترتبط بهذه الورقة، مع بقاء بعض بنود Year 1-Year 2 كمدخلات خطة إدارة معتمدة موضحة صراحة في أوراقها. | D5: =IFERROR(HYPERLINK("#'Assumptions'!A1","Open →"),"Open →") -> Open →
A6: 3 | B6: Capital | C6: جدول تحصيل رأس المال من المساهمين الأربعة على دفعات ربع سنوية تبدأ قبل Year 1 وتستكمل خلال Year 2 حتى بلوغ 75 مليون جنيه. | D6: =IFERROR(HYPERLINK("#'Capital'!A1","Open →"),"Open →") -> Open →
A7: 4 | B7: Products | C7: القطاعات والمنتجات التي تستهدفها فليكسي في نشاط التأجير التمويلي. | D7: =IFERROR(HYPERLINK("#'Products'!A1","Open →"),"Open →") -> Open →
A8: 5 | B8: Staff | C8: الهيكل الوظيفي وتكلفة العاملين سنويا حتى نهاية Year 5، شاملا وظيفة مسؤول مكافحة غسل الأموال وتمويل الإرهاب. | D8: =IFERROR(HYPERLINK("#'Staff'!A1","Open →"),"Open →") -> Open →
A9: 6 | B9: Opex | C9: تفصيل المصروفات الإدارية والعمومية بندا ببند (تقنية، تسويق، إيجارات). | D9: =IFERROR(HYPERLINK("#'Opex'!A1","Open →"),"Open →") -> Open →
A10: 7 | B10: Originations | C10: خطة المنح الشهرية والربع سنوية على 60 شهرا، موزعة من الحجم السنوي في Assumptions وفق التوزيع الموسمي المعتمد، مع تجميع سنوي واختبارات ربط. | D10: =IFERROR(HYPERLINK("#'Originations'!A1","Open →"),"Open →") -> Open →
A11: 8 | B11: Cohort Principal | C11: جدول سنوي لتطور أصل المحفظة: رصيد أول السنة + الأصل الممول من المنح - تحصيل/استنفاد الأصل = رصيد آخر السنة، مع اختبار ربط. | D11: =IFERROR(HYPERLINK("#'Cohort Principal'!A1","Open →"),"Open →") -> Open →
A12: 9 | B12: Cohort Interest | C12: جدول سنوي لعوائد التأجير: Year 1-Year 2 مدخلات خطة إدارة معتمدة لعدم توافر جدول EIR/عقود شهري مستقل؛ Year 3-Year 5 تحسب من متوسط المحفظة × العائد السنوي. | D12: =IFERROR(HYPERLINK("#'Cohort Interest'!A1","Open →"),"Open →") -> Open →
A13: 10 | B13: Cohort Fees | C13: جدول سنوي لرسوم الخدمات: المنح × نسبة الرسوم المعتمدة (Year 1=5%، Year 2=7%، ومن Year 3=6%)، مع إظهار دعم/خدمات مساندة منفصلة عند وجودها. | D13: =IFERROR(HYPERLINK("#'Cohort Fees'!A1","Open →"),"Open →") -> Open →
A14: 11 | B14: Monthly Model | C14: تجميع شهري على 60 شهرا للتدفقات والنقدية والدين والرافعة. يستخدم كأساس لاختبارات التمويل والرافعة الشهرية، كما يغذي مؤشرات السيولة التخطيطية التي تستكمل ببيانات الآجال التعاقدية في Funding & Liquidity. | D14: =IFERROR(HYPERLINK("#'Monthly Model'!A1","Open →"),"Open →") -> Open →
A15: 12 | B15: Income Statement | C15: قائمة الدخل التقديرية لخمس سنوات، متضمنة جدول تسوية ضريبية كاملا (ترحيل خسارة Year 1 مقابل ربح Year 2). | D15: =IFERROR(HYPERLINK("#'Income Statement'!A1","Open →"),"Open →") -> Open →
A16: 13 | B16: Balance Sheet | C16: قائمة المركز المالي التقديرية لخمس سنوات، مع فحص توازن آلي يجب أن يساوي صفرا كل سنة. | D16: =IFERROR(HYPERLINK("#'Balance Sheet'!A1","Open →"),"Open →") -> Open →
A17: 14 | B17: Cash Flow | C17: قائمة التدفقات النقدية (تشغيلي/استثماري/تمويلي)، مع ربط آلي للرصيد الختامي بالميزانية. | D17: =IFERROR(HYPERLINK("#'Cash Flow'!A1","Open →"),"Open →") -> Open →
A18: 15 | B18: Investments | C18: الخطة الاستثمارية لخمس سنوات على ست قنوات (منصة التأجير، الأمن السيبراني، معدات، إلخ). | D18: =IFERROR(HYPERLINK("#'Investments'!A1","Open →"),"Open →") -> Open →
A19: 16 | B19: Feasibility | C19: مؤشرات الجدوى: NPV، IRR، فترة الاسترداد، ARR، تكلفة رأس المال WACC، ودليل الربحية PI. | D19: =IFERROR(HYPERLINK("#'Feasibility'!A1","Open →"),"Open →") -> Open →
A20: 17 | B20: Ratios | C20: النسب المالية: العائد على الأصول ROA، العائد على حقوق الملكية ROE، العائد على الاستثمار ROI، ومؤشرات سيولة تكميلية. | D20: =IFERROR(HYPERLINK("#'Ratios'!A1","Open →"),"Open →") -> Open →
A21: 18 | B21: Scenarios | C21: ثلاثة سيناريوهات تجارية عامة (أفضل/أساسي/أسوأ) لأثر التشغيل على الربحية - سيناريوهات نشاط عامة، غير مرتبطة بسقف الرافعة الرقابي (راجع Scenario - Slower Year 2 لهذا الغرض). | D21: =IFERROR(HYPERLINK("#'Scenarios'!A1","Open →"),"Open →") -> Open →
A22: 19 | B22: Sensitivity | C22: حساسية صافي ربح Year 5 لتغير عائد العميل وحجم المنح معا. | D22: =IFERROR(HYPERLINK("#'Sensitivity'!A1","Open →"),"Open →") -> Open →
A23: 20 | B23: Break Even | C23: نقطة تعادل حجم المحفظة والمنح المطلوبين سنويا، وهامش الأمان الفعلي. | D23: =IFERROR(HYPERLINK("#'Break Even'!A1","Open →"),"Open →") -> Open →
A24: 21 | B24: Compliance | C24: مصفوفة تقابل كل بند من الـ14 بندا الأساسية في خطاب الهيئة بمكان استيفائه في الملف - للمراجع السريع قبل التقديم. | D24: =IFERROR(HYPERLINK("#'Compliance'!A1","Open →"),"Open →") -> Open →
A25: 22 | B25: Checks | C25: اختبارات ذاتية للتأكد من سلامة الأرقام حسابيا (توازن الميزانية، تطابق التدفقات، تسوية الدين) - أداة مراجعة داخلية للنموذج، وليست موجهة للهيئة. | D25: =IFERROR(HYPERLINK("#'Checks'!A1","Open →"),"Open →") -> Open →
A26: 23 | B26: Sources | C26: سجل بكل افتراض غير مؤكد بعد ومصدره ومكان استخدامه، بما في ذلك روابط النصوص الرقابية الرسمية (قرار 268/2023 وقرار 137/2025). | D26: =IFERROR(HYPERLINK("#'Sources'!A1","Open →"),"Open →") -> Open →
A27: 24 | B27: Formula Map | C27: دليل مختصر يوضح في أي ورقة وأي صف تحسب كل نسبة أو مؤشر رئيسي. | D27: =IFERROR(HYPERLINK("#'Formula Map'!A1","Open →"),"Open →") -> Open →
A28: 25 | B28: Regulatory Capital Plan | C28: المصدر الأساسي لحساب القاعدة الرأسمالية، الأصول المرجحة بالمخاطر، CAR، وسقف الرافعة (4×/9×) بالتفصيل - كل الأوراق الأخرى التي تعرض هذه الأرقام (Basel III، Compliance، Checks) تسحبها من هنا. | D28: =IFERROR(HYPERLINK("#'Regulatory Capital Plan'!A1","Open →"),"Open →") -> Open →
A29: 26 | B29: Funding & Liquidity | C29: تفصيل مصادر التمويل وتكلفتها، اختبار الرافعة الشهري خلال Year 2، وسلمي LCR (30 يوما) وNSFR (حسب الأجل المتبقي) التفصيليين. | D29: =IFERROR(HYPERLINK("#'Funding & Liquidity'!A1","Open →"),"Open →") -> Open →
A30: 27 | B30: Scenario - Slower Year 2 | C30: أداة إدارة عملية لفجوة سقف الرافعة عبر تباطؤ نمو Year 2 (تخفيض معدل المنح والتمويل معا) - وليس سيناريو تجاري عام. | D30: =IFERROR(HYPERLINK("#'Scenario - Slower 2028'!A1","Open →"),"Open →") -> Open →
A31: 28 | B31: Scenario - Standby Capital | C31: أداة إدارة عملية لفجوة سقف الرافعة عبر ضخ رأس مال احتياطي من المساهمين، بحساب الحد الأدنى الكافي تلقائيا. | D31: =IFERROR(HYPERLINK("#'Scenario - Standby Capital'!A1","Open →"),"Open →") -> Open →
A32: 29 | B32: رد الملاحظات | C32: رد مباشر ومرقم على كل ملاحظة وردت في خطاب الهيئة، مع رابط لكل رد يوصل إلى الورقة التي تثبته فعليا. | D32: =IFERROR(HYPERLINK("#'رد الملاحظات'!A1","Open →"),"Open →") -> Open →
A33: 30 | B33: Basel III | C33: يجمع أرقام كفاية رأس المال (من Regulatory Capital Plan) ونسب السيولة (من Funding & Liquidity) في عرض واحد متكامل لبازل 3، ويضيف تفاصيل غير موجودة في مكان آخر: الانكشافات غير المرجحة، تصنيف مؤشر الأعمال، جدول تركز العملاء، وحساسية CAR لمعامل مخاطر التشغيل. ملاحظة: نحو ثلث صفوف الجزء الأول من هذه الورقة نسخة مباشرة من Regulatory Capital Plan بغرض تجميعها في عرض واحد يخص بازل 3 تحديدا. | D33: =IFERROR(HYPERLINK("#'Basel III'!A1","Open →"),"Open →") -> Open →
A34: 31 | B34: Regulatory Data Requirements | C34: قائمة بكل مستند أو بيان مطلوب من الإدارة ولم يتوفر بعد، مع الجهة المسؤولة والموعد المستهدف وأثر عدم التوفر. | D34: =IFERROR(HYPERLINK("#'Regulatory Data Requirements'!A1","Open →"),"Open →") -> Open →
A35: 32 | B35: جاهزية التقديم | C35: لوحة ملخصة نهائية بكل نتائج الالتزام الرئيسية (الرافعة، CAR، LCR، NSFR)، وقرار صريح بجاهزية الملف للتقديم كدراسة جدوى وليس كإقرار امتثال فعلي. | D35: =IFERROR(HYPERLINK("#'جاهزية التقديم'!A1","Open →"),"Open →") -> Open →

Sheet Assumptions
A1: Flexy - الافتراضات الرئيسية للنموذج المالي
A3: البند | B3: Year 1 | C3: Year 2 | D3: Year 3 | E3: Year 4 | F3: Year 5
A4: حجم المنح السنوي | B4: 27750000 | C4: 527500000 | D4: 700000000 | E4: 1350000000 | F4: 2500000000
A5: خطة التشغيل السنوية | B5: =B4 -> 27750000 | C5: =C4 -> 527500000 | D5: =D4 -> 700000000 | E5: =E4 -> 1350000000 | F5: =F4 -> 2500000000
A6: العائد السنوي الاسمي على رصيد العميل | B6: 0.34 | C6: 0.32 | D6: 0.3 | E6: 0.28 | F6: 0.26
A7: سعر مرجعي تقديري | B7: 0.21 | C7: 0.19 | D7: 0.17 | E7: 0.15 | F7: 0.14
A8: هامش البنك فوق السعر المرجعي | B8: 0.03 | C8: 0.03 | D8: 0.03 | E8: 0.03 | F8: 0.03
A9: تكلفة الاقتراض السنوية | B9: 0.24 | C9: 0.22 | D9: 0.2 | E9: 0.18 | F9: 0.17
A10: متوسط قيمة العقد | B10: 150000 | C10: 315868.26 | D10: 888461.54 | E10: 1100000 | F10: 1350000
A11: الإنفاق الرأسمالي | B11: 4302000 | C11: 500000 | D11: 1000000 | E11: 1500000 | F11: 2000000
A12: عدد مكاتب التوقيع وخدمات الأصول | B12: 8 | C12: 8 | D12: 8 | E12: 15 | F12: 22
A13: الحد الأدنى للسيولة | B13: 2500000 | C13: 25000000 | D13: 25000000 | E13: 50000000 | F13: 100000000
A15: افتراضات ثابتة وقانونية
A16: Establishment Phase | B16: 46296 | C16: مؤكد من الإدارة
A17: Start of Operations Phase | B17: 46388 | C17: ترخيص مبدئي/بدء النشاط
A18: First Contract Phase | B18: 46419 | C18: خلال شهر من ترخيص البدء
A19: Target Final License Phase | B19: 47026 | C19: Management planning assumption: capital completion and target final license during Year 2
A20: رأس المال المرخص | B20: 75000000 | C20: مؤكد من الإدارة
A21: رأس المال المصدر والمدفوع عند البداية | B21: 15000000 | C21: مؤكد من الإدارة
A22: القيمة الاسمية المقترحة للسهم | B22: 1 | C22: افتراض قانوني لحين اعتماد عقد التأسيس
A23: إجمالي الأسهم عند استكمال 75 مليون | B23: =C91/$B$22 -> 75000000 | C23: رأس المال ÷ القيمة الاسمية
A24: صافي فاقد ائتماني على الأقساط المستحقة - افتراض تخطيطي | C24: 4x قبل الترخيص النهائي و9x بعده
A25: نسبة مقدم العميل / الجزء غير الممول من قيمة الأصل | B25: 0.15 | C25: افتراض تشغيلي مستخدم في احتساب صافي أصل محفظة التأجير؛ ليس نسبة مخصص خسائر ائتمانية
A26: نسبة الرسوم الإدارية حسب السنة | B26: 0.05 | C26: 0.07 | D26: 0.06 | E26: 0.06 | F26: 0.06
A27: نسبة الاعتراف بالرسوم عند المنح - سياسة محاسبية مستهدفة (غير مطبقة في القوائم المقفلة حاليا) | B27: 0.7 | C27: مقابل خدمات منفصلة - تخضع لاعتماد المراجع
A28: نسبة الرسوم المؤجلة - سياسة محاسبية مستهدفة (غير مطبقة في القوائم المقفلة حاليا) | B28: =1-B27 -> 0.3 | C28: تستهلك على مدة العقد
A29: متوسط مدة العقد - شهر | B29: 30 | C29: الغالبية 24-36 شهر
A30: صافي فاقد ائتماني على الأقساط المستحقة | B30: 0.02 | C30: افتراض تحفظي قابل للتعديل
A31: نسبة مخصص الخسائر الائتمانية التخطيطي من إجمالي المحفظة الختامية (ليس نموذج EAS 47 كامل) | B31: 0.03 | C31: افتراض دراسة جدوى؛ إلى حين بناء نموذج EAS 47 ببيانات PD/LGD/EAD والمراحل الائتمانية
A32: نسبة سداد أصل تمويل البنك من تحصيلات الأصل | B32: 0.75 | C32: Cash sweep
A33: ضريبة الدخل | B33: 0.225 | C33: ضريبة الشركات
A34: زيادة الرواتب السنوية | B34: 0.2 | C34: طبقا لجدول الهيكل الوظيفي المرجعي
A35: زيادة المصروفات السنوية | B35: 0.1 | C35: تقدير إداري
A36: معدل الحوافز المتغيرة الضمني من موازنة العاملين المعتمدة | B36: =IFERROR(Staff!H10/SUM(Staff!H4:H9,Staff!H11:H20),0) -> 0 | C36: =IFERROR(Staff!I10/SUM(Staff!I4:I9,Staff!I11:I20),0) -> 0.16662508 | D36: =IFERROR(Staff!J10/SUM(Staff!J4:J9,Staff!J11:J20),0) -> 0.36284717 | E36: =IFERROR(Staff!K10/SUM(Staff!K4:K9,Staff!K11:K20),0) -> 0.3 | F36: =IFERROR(Staff!L10/SUM(Staff!L4:L9,Staff!L11:L20),0) -> 0.3
A37: معدل حافز إنتاج مرجعي على منح الشهر السابق (مرجع تشغيلي؛ غير مستخدم كمعامل موازنة سنوي) | B37: 0.005 | C37: مرتبطة بالإنتاج
A38: نسبة الرسوم المتغيرة/بوابات الدفع من التحصيلات | B38: 0.002 | C38: تقدير
A39: تكلفة حقوق الملكية | B39: 0.25 | C39: معدل خصم اسمي بالجنيه - افتراض تقييم
A40: مضاعف الربحية النهائي | B40: 8 | C40: حالة أساسية للتقييم عند نهاية Year 5
A41: نسبة الاحتياطي القانوني من الربح | B41: 0.05 | C41: حتى 50% من رأس المال
A42: أقصى رصيد للاحتياطي القانوني | B42: 0.5 | C42: من رأس المال المصدر
...

Sheet Capital
A1: رأس المال والتزامات المساهمين
A3: Plan Stage | B3: البيان | C3: إجمالي الزيادة | D3: Finvera | E3: El-Mobadara | F3: CDS | G3: Egabi
A4: 46296 | B4: رأس المال المصدر والمدفوع عند التأسيس | C4: 15000000 | D4: 3750000 | E4: 3750000 | F4: 3750000 | G4: 3750000
A5: 46478 | B5: دفعة ربع سنوية | C5: 3750000 | D5: 937500 | E5: 937500 | F5: 937500 | G5: 937500
A6: 46569 | B6: دفعة ربع سنوية | C6: 3750000 | D6: 937500 | E6: 937500 | F6: 937500 | G6: 937500
A7: 46661 | B7: دفعة ربع سنوية | C7: 3750000 | D7: 937500 | E7: 937500 | F7: 937500 | G7: 937500
A8: 46752 | B8: استكمال 30 مليون | C8: 3750000 | D8: 937500 | E8: 937500 | F8: 937500 | G8: 937500
A9: 46783 | B9: دفعة لاستكمال رأس المال | C9: 15000000 | D9: 3750000 | E9: 3750000 | F9: 3750000 | G9: 3750000
A10: 46904 | B10: دفعة لاستكمال رأس المال | C10: 15000000 | D10: 3750000 | E10: 3750000 | F10: 3750000 | G10: 3750000
A11: 47026 | B11: استكمال 75 مليون | C11: 15000000 | D11: 3750000 | E11: 3750000 | F11: 3750000 | G11: 3750000
A13: بيانات رأس المال والأسهم
A14: رأس المال المرخص به | B14: 75000000
A15: رأس المال المصدر والمدفوع عند البداية | B15: 15000000
A16: رأس المال المصدر والمدفوع بعد الاستكمال | B16: 75000000
A17: القيمة الاسمية للسهم | B17: 1
A18: إجمالي عدد الأسهم بعد الاستكمال | B18: 75000000
A19: إجمالي عدد الأسهم المصرح بها | B19: =B14/B17 -> 75000000
A20: المساهمون
A21: المساهم | B21: نسبة الملكية | C21: رأس المال النقدي | D21: مصروفات تأسيس مسددة | E21: إجمالي التزام نقدي | F21: حد الإدارة | G21: هامش
A22: Finvera | B22: 0.25 | C22: 18750000 | D22: 64519.07 | E22: 18814519 | F22: 20000000 | G22: 1185480.9
A23: El-Mobadara | B23: 0.25 | C23: 18750000 | D23: 64519.07 | E23: 18814519 | F23: 20000000 | G23: 1185480.9
A24: CDS | B24: 0.25 | C24: 18750000 | D24: 64519.07 | E24: 18814519 | F24: 20000000 | G24: 1185480.9
A25: Egabi | B25: 0.25 | C25: 18750000 | D25: 64519.07 | E25: 18814519 | F25: 20000000 | G25: 1185480.9
A27: مصروفات التأسيس البالغة 258,076.28 جنيه تحملها المساهمون بالتساوي وفق نسب الملكية، ولا تدخل في القاعدة الرأسمالية التنظيمية ما لم يعتمد المستشار القانوني ومراقب الحسابات معالجتها كحقوق ملكية مؤهلة.

Sheet Products
A1: المنتجات والقطاعات المستهدفة
A3: القطاع | B3: المزيج | C3: متوسط العقد | D3: الحد الأدنى | E3: الحد الأقصى الإرشادي | F3: المقدم الأدنى | G3: المقدم الأقصى | H3: المدة الدنيا - شهر | I3: المدة القصوى - شهر | J3: ملاحظات
A4: معدات صناعية | B4: 0.25 | C4: 250000 | D4: 50000 | E4: 500000 | F4: 0.1 | G4: 0.2 | H4: 12 | I4: 60 | J4: طبقا للعمر الإنتاجي للأصل
A5: معدات زراعية | B5: 0.2 | C5: 300000 | D5: 50000 | E5: 500000 | F5: 0.1 | G5: 0.2 | H5: 6 | I5: 48 | J5: يجوز تحصيل ربع/نصف سنوي للأنشطة الموسمية
A6: معدات طبية | B6: 0.2 | C6: 150000 | D6: 50000 | E6: 500000 | F6: 0.1 | G6: 0.2 | H6: 12 | I6: 60 | J6: موردون معتمدون وتأمين على الأصل
A7: نقل تجاري خفيف | B7: 0.25 | C7: 500000 | D7: 100000 | E7: 1000000 | F7: 0.1 | G7: 0.2 | H7: 12 | I7: 60 | J7: التأمين والترخيص شرط صرف
A8: قطاعات أخرى | B8: 0.1 | C8: 275000 | D8: 50000 | E8: 500000 | F8: 0.1 | G8: 0.2 | H8: 6 | I8: 48 | J8: تخضع لحدود التركز والسياسة الائتمانية
A10: مؤشر | B10: القيمة | C10: الفحص
A11: إجمالي المزيج | B11: =SUM(B4:B8) -> 1 | C11: =IF(ABS(B11-100%)<0.0001,"OK","راجع المزيج") -> OK
A12: متوسط العقد المرجح | B12: =SUMPRODUCT(B4:B8,C4:C8) -> 305000 | C12: استرشادي؛ يختلف سنويا حسب خطة المنح
A14: قواعد التسعير | B14: سعر العميل ثابت لكل عقد موقع، ويحدد عند المنح وفق تكلفة تمويل البنك + هامش مخاطر وتشغيل.
A15: السداد المعجل | B15: خصم العوائد غير المستحقة مع عمولة سداد معجل 5%-10% وفق العقد والقواعد المعتمدة.
A16: التأخير | B16: غرامة شهرية على الأجرة المتأخرة وفق العقد وبما لا يخالف الضوابط؛ لم يفترض دخل منها في الحالة الأساسية.
A17: التملك | B17: سعر رمزي جنيه واحد بعد سداد جميع الالتزامات والمصروفات والأقساط.

Sheet Staff
A1: الهيكل الوظيفي وتكلفة العمالة
A3: الوظيفة | B3: الراتب الشهري الأساسي Year 1 | C3: Year 1 FTE | D3: Year 2 FTE | E3: Year 3 FTE | F3: Year 4 FTE | G3: Year 5 FTE | H3: Year 1 Cost | I3: Year 2 Cost | J3: Year 3 Cost | K3: Year 4 Cost | L3: Year 5 Cost | M3: ملاحظة رقابية
A4: الرئيس التنفيذي والعضو المنتدب | B4: 150000 | C4: 1 | D4: 1 | E4: 1 | F4: 1 | G4: 1 | H4: =ROUND($B4*C4*12*(1+Assumptions!$B$34)^0,2) -> 1800000 | I4: =ROUND($B4*D4*12*(1+Assumptions!$B$34)^1,2) -> 2160000 | J4: =ROUND($B4*E4*12*(1+Assumptions!$B$34)^2,2) -> 2592000 | K4: =ROUND($B4*F4*12*(1+Assumptions!$B$34)^3,2) -> 3110400 | L4: =ROUND($B4*G4*12*(1+Assumptions!$B$34)^4,2) -> 3732480 | M4: إدارة تنفيذية
A5: نائب الرئيس التنفيذي/عضو مجلس الإدارة | B5: 120000 | C5: 1 | D5: 1 | E5: 1 | F5: 1 | G5: 1 | H5: =ROUND($B5*C5*12*(1+Assumptions!$B$34)^0,2) -> 1440000 | I5: =ROUND($B5*D5*12*(1+Assumptions!$B$34)^1,2) -> 1728000 | J5: =ROUND($B5*E5*12*(1+Assumptions!$B$34)^2,2) -> 2073600 | K5: =ROUND($B5*F5*12*(1+Assumptions!$B$34)^3,2) -> 2488320 | L5: =ROUND($B5*G5*12*(1+Assumptions!$B$34)^4,2) -> 2985984 | M5: حوكمة
A6: المدير المالي والإداري | B6: 65000 | C6: 1 | D6: 1 | E6: 1 | F6: 1 | G6: 1 | H6: =ROUND($B6*C6*12*(1+Assumptions!$B$34)^0,2) -> 780000 | I6: =ROUND($B6*D6*12*(1+Assumptions!$B$34)^1,2) -> 936000 | J6: =ROUND($B6*E6*12*(1+Assumptions!$B$34)^2,2) -> 1123200 | K6: =ROUND($B6*F6*12*(1+Assumptions!$B$34)^3,2) -> 1347840 | L6: =ROUND($B6*G6*12*(1+Assumptions!$B$34)^4,2) -> 1617408 | M6: قوائم وسيولة
A7: مدير المخاطر | B7: 35000 | C7: 1 | D7: 1 | E7: 1 | F7: 1 | G7: 1 | H7: =ROUND($B7*C7*12*(1+Assumptions!$B$34)^0,2) -> 420000 | I7: =ROUND($B7*D7*12*(1+Assumptions!$B$34)^1,2) -> 504000 | J7: =ROUND($B7*E7*12*(1+Assumptions!$B$34)^2,2) -> 604800 | K7: =ROUND($B7*F7*12*(1+Assumptions!$B$34)^3,2) -> 725760 | L7: =ROUND($B7*G7*12*(1+Assumptions!$B$34)^4,2) -> 870912 | M7: مستقل رقابيا
A8: مدير التقنية | B8: 60000 | C8: 1 | D8: 1 | E8: 1 | F8: 1 | G8: 1 | H8: =ROUND($B8*C8*12*(1+Assumptions!$B$34)^0,2) -> 720000 | I8: =ROUND($B8*D8*12*(1+Assumptions!$B$34)^1,2) -> 864000 | J8: =ROUND($B8*E8*12*(1+Assumptions!$B$34)^2,2) -> 1036800 | K8: =ROUND($B8*F8*12*(1+Assumptions!$B$34)^3,2) -> 1244160 | L8: =ROUND($B8*G8*12*(1+Assumptions!$B$34)^4,2) -> 1492992 | M8: حماية واستمرارية الأعمال
A9: مسؤولو التقنية | B9: 36000 | C9: 3 | D9: 3 | E9: 3 | F9: 3 | G9: 3 | H9: =ROUND($B9*C9*12*(1+Assumptions!$B$34)^0,2) -> 1296000 | I9: =ROUND($B9*D9*12*(1+Assumptions!$B$34)^1,2) -> 1555200 | J9: =ROUND($B9*E9*12*(1+Assumptions!$B$34)^2,2) -> 1866240 | K9: =ROUND($B9*F9*12*(1+Assumptions!$B$34)^3,2) -> 2239488 | L9: =ROUND($B9*G9*12*(1+Assumptions!$B$34)^4,2) -> 2687385.6 | M9: توسع تقني متدرج
A10: حوافز ومكافآت أداء متغيرة ضمن موازنة العاملين المعتمدة | C10: 0 | D10: 0 | E10: 0 | F10: 0 | G10: 0 | H10: =MAX(0,H$22-SUM(H$4:H$9,H$11:H$20)) -> 0 | I10: =MAX(0,I$22-SUM(I$4:I$9,I$11:I$20)) -> 2230665.6 | J10: =MAX(0,J$22-SUM(J$4:J$9,J$11:J$20)) -> 5829067.7 | K10: =MAX(0,K$22-SUM(K$4:K$9,K$11:K$20)) -> 5783328.5 | L10: =MAX(0,L$22-SUM(L$4:L$9,L$11:L$20)) -> 6939994.2 | M10: رصيد موازنة متغير: إجمالي موازنة العاملين المعتمدة ناقص الرواتب الثابتة؛ الصرف الفعلي يخضع لمؤشرات الإنتاج والأداء.
A11: مسؤول الالتزام | B11: 15000 | C11: 1 | D11: 1 | E11: 1 | F11: 1 | G11: 1 | H11: =ROUND($B11*C11*12*(1+Assumptions!$B$34)^0,2) -> 180000 | I11: =ROUND($B11*D11*12*(1+Assumptions!$B$34)^1,2) -> 216000 | J11: =ROUND($B11*E11*12*(1+Assumptions!$B$34)^2,2) -> 259200 | K11: =ROUND($B11*F11*12*(1+Assumptions!$B$34)^3,2) -> 311040 | L11: =ROUND($B11*G11*12*(1+Assumptions!$B$34)^4,2) -> 373248 | M11: تقارير مباشرة للمجلس/لجنة المراجعة
A12: مسؤول مكافحة غسل الأموال وتمويل الإرهاب | B12: 15000 | C12: 1 | D12: 1 | E12: 1 | F12: 1 | G12: 1 | H12: =ROUND($B12*C12*12*(1+Assumptions!$B$34)^0,2) -> 180000 | I12: =ROUND($B12*D12*12*(1+Assumptions!$B$34)^1,2) -> 216000 | J12: =ROUND($B12*E12*12*(1+Assumptions!$B$34)^2,2) -> 259200 | K12: =ROUND($B12*F12*12*(1+Assumptions!$B$34)^3,2) -> 311040 | L12: =ROUND($B12*G12*12*(1+Assumptions!$B$34)^4,2) -> 373248 | M12: وظيفة مستقلة واتصال مباشر بالمجلس والجهات المختصة
A13: مسؤول المراجعة الداخلية | B13: 25000 | C13: 1 | D13: 1 | E13: 1 | F13: 1 | G13: 1 | H13: =ROUND($B13*C13*12*(1+Assumptions!$B$34)^0,2) -> 300000 | I13: =ROUND($B13*D13*12*(1+Assumptions!$B$34)^1,2) -> 360000 | J13: =ROUND($B13*E13*12*(1+Assumptions!$B$34)^2,2) -> 432000 | K13: =ROUND($B13*F13*12*(1+Assumptions!$B$34)^3,2) -> 518400 | L13: =ROUND($B13*G13*12*(1+Assumptions!$B$34)^4,2) -> 622080 | M13: استقلال وظيفي
A14: مسؤول الموارد البشرية | B14: 15000 | C14: 1 | D14: 1 | E14: 1 | F14: 1 | G14: 1 | H14: =ROUND($B14*C14*12*(1+Assumptions!$B$34)^0,2) -> 180000 | I14: =ROUND($B14*D14*12*(1+Assumptions!$B$34)^1,2) -> 216000 | J14: =ROUND($B14*E14*12*(1+Assumptions!$B$34)^2,2) -> 259200 | K14: =ROUND($B14*F14*12*(1+Assumptions!$B$34)^3,2) -> 311040 | L14: =ROUND($B14*G14*12*(1+Assumptions!$B$34)^4,2) -> 373248 | M14: دعم إداري
A15: فريق مخاطر الائتمان | B15: 15000 | C15: 2 | D15: 2 | E15: 2 | F15: 2 | G15: 2 | H15: =ROUND($B15*C15*12*(1+Assumptions!$B$34)^0,2) -> 360000 | I15: =ROUND($B15*D15*12*(1+Assumptions!$B$34)^1,2) -> 432000 | J15: =ROUND($B15*E15*12*(1+Assumptions!$B$34)^2,2) -> 518400 | K15: =ROUND($B15*F15*12*(1+Assumptions!$B$34)^3,2) -> 622080 | L15: =ROUND($B15*G15*12*(1+Assumptions!$B$34)^4,2) -> 746496 | M15: يتدرج مع المحفظة
A16: المشتريات وإدارة الموردين | B16: 15000 | C16: 3 | D16: 3 | E16: 3 | F16: 3 | G16: 3 | H16: =ROUND($B16*C16*12*(1+Assumptions!$B$34)^0,2) -> 540000 | I16: =ROUND($B16*D16*12*(1+Assumptions!$B$34)^1,2) -> 648000 | J16: =ROUND($B16*E16*12*(1+Assumptions!$B$34)^2,2) -> 777600 | K16: =ROUND($B16*F16*12*(1+Assumptions!$B$34)^3,2) -> 933120 | L16: =ROUND($B16*G16*12*(1+Assumptions!$B$34)^4,2) -> 1119744 | M16: تحقق من الأصل والمورد
A17: مسؤولو التوقيعات والمعاينات الميدانية | B17: 14000 | C17: 8 | D17: 8 | E17: 8 | F17: 8 | G17: 8 | H17: =ROUND($B17*C17*12*(1+Assumptions!$B$34)^0,2) -> 1344000 | I17: =ROUND($B17*D17*12*(1+Assumptions!$B$34)^1,2) -> 1612800 | J17: =ROUND($B17*E17*12*(1+Assumptions!$B$34)^2,2) -> 1935360 | K17: =ROUND($B17*F17*12*(1+Assumptions!$B$34)^3,2) -> 2322432 | L17: =ROUND($B17*G17*12*(1+Assumptions!$B$34)^4,2) -> 2786918.4 | M17: توقيع، استلام/تسليم، معاينة، متابعة واسترداد
A18: التسويق والتواصل الرقمي | B18: 14676 | C18: 1 | D18: 1 | E18: 1 | F18: 1 | G18: 1 | H18: =ROUND($B18*C18*12*(1+Assumptions!$B$34)^0,2) -> 176112 | I18: =ROUND($B18*D18*12*(1+Assumptions!$B$34)^1,2) -> 211334.4 | J18: =ROUND($B18*E18*12*(1+Assumptions!$B$34)^2,2) -> 253601.28 | K18: =ROUND($B18*F18*12*(1+Assumptions!$B$34)^3,2) -> 304321.54 | L18: =ROUND($B18*G18*12*(1+Assumptions!$B$34)^4,2) -> 365185.84 | M18: توسع مرحلي
A19: مسؤولو التأجير التمويلي داخل الفروع | B19: 12000 | C19: 8 | D19: 8 | E19: 8 | F19: 8 | G19: 8 | H19: =ROUND($B19*C19*12*(1+Assumptions!$B$34)^0,2) -> 1152000 | I19: =ROUND($B19*D19*12*(1+Assumptions!$B$34)^1,2) -> 1382400 | J19: =ROUND($B19*E19*12*(1+Assumptions!$B$34)^2,2) -> 1658880 | K19: =ROUND($B19*F19*12*(1+Assumptions!$B$34)^3,2) -> 1990656 | L19: =ROUND($B19*G19*12*(1+Assumptions!$B$34)^4,2) -> 2388787.2 | M19: مرتبط بحجم المنح
A20: مساعدون إداريون | B20: 12000 | C20: 2 | D20: 2 | E20: 2 | F20: 2 | G20: 2 | H20: =ROUND($B20*C20*12*(1+Assumptions!$B$34)^0,2) -> 288000 | I20: =ROUND($B20*D20*12*(1+Assumptions!$B$34)^1,2) -> 345600 | J20: =ROUND($B20*E20*12*(1+Assumptions!$B$34)^2,2) -> 414720 | K20: =ROUND($B20*F20*12*(1+Assumptions!$B$34)^3,2) -> 497664 | L20: =ROUND($B20*G20*12*(1+Assumptions!$B$34)^4,2) -> 597196.8 | M20: دعم
A21: الإجمالي | C21: =SUM(C4:C20) -> 36 | D21: =SUM(D4:D20) -> 36 | E21: =SUM(E4:E20) -> 36 | F21: =SUM(F4:F20) -> 36 | G21: =SUM(G4:G20) -> 36 | H21: =SUM(H4:H20) -> 11156112 | I21: =SUM(I4:I20) -> 15618000 | J21: =SUM(J4:J20) -> 21893869 | ... L21: =SUM(L4:L20) -> 30073308
A22: إجمالي موازنة العاملين المعتمدة | B22: إجمالي سنوي معتمد من الإدارة | H22: 11156112 | I22: 15618000 | J22: 21893869 | K22: 25061090 | L22: 30073308
A23: موقع مسؤول مكافحة غسل الأموال | B23: وظيفة رقابية مستقلة عن المبيعات والائتمان؛ ترتبط وظيفيا بلجنة المراجعة/مجلس الإدارة وإداريا بالرئيس التنفيذي
A24: اختصاصات أساسية | B24: تقييم المخاطر، KYC/UBO، مراقبة العمليات، فحص الجزاءات، البلاغات، السجلات والتدريب
A25: أساس العدد والتكلفة | B25: إجمالي القوى العاملة 36 موظفا في كل سنة، مع زيادة سنوية 20% وحوافز إنتاج وفق جدول الافتراضات. لا توجد وظيفة مدير تشغيل مخصصة في الموازنة (العدد صفر في المصدر)، وتتولى الإدارة التنفيذية مهام الإشراف التشغيلي في مرحلة الإطلاق. تم تخصيص وظيفة مستقلة لمسؤول مكافحة غسل الأموال داخل نفس إجمالي العدد والتكلفة.

Sheet Opex
A1: المصروفات الإدارية والعمومية السنوية
A3: البند | B3: تكلفة الوحدة شهريا | C3: Year 1 Units | D3: Year 2 Units | E3: Year 3 Units | F3: Year 4 Units | G3: Year 5 Units | H3: Year 1 | I3: Year 2 | J3: Year 3 | K3: Year 4 | L3: Year 5
A4: إيجار المركز الرئيسي | B4: 80000 | C4: 1 | D4: 1 | E4: 1 | F4: 1 | G4: 1 | H4: =$B4*C4*12*(1+Assumptions!$B$35)^0*Assumptions!$B$66 -> 620307.69 | I4: =$B4*D4*12*(1+Assumptions!$B$35)^1*Assumptions!$C$66 -> 1036800 | J4: =ROUND($B4*E4*12*(1+Assumptions!$B$35)^2*Assumptions!$D$66,2) -> 1161600 | K4: =ROUND($B4*F4*12*(1+Assumptions!$B$35)^3*Assumptions!$E$66,2) -> 1277760 | L4: =ROUND($B4*G4*12*(1+Assumptions!$B$35)^4*Assumptions!$F$66,2) -> 1405536
A5: إيجار مكاتب التوقيع وخدمات الأصول | B5: 30000 | C5: 8 | D5: 8 | E5: 8 | F5: 15 | G5: 22 | H5: =$B5*C5*12*(1+Assumptions!$B$35)^0*Assumptions!$B$66 -> 1860923.1 | I5: =$B5*D5*12*(1+Assumptions!$B$35)^1*Assumptions!$C$66 -> 3110400 | J5: =ROUND($B5*E5*12*(1+Assumptions!$B$35)^2*Assumptions!$D$66,2) -> 3484800 | K5: =ROUND($B5*F5*12*(1+Assumptions!$B$35)^3*Assumptions!$E$66,2) -> 7187400 | L5: =ROUND($B5*G5*12*(1+Assumptions!$B$35)^4*Assumptions!$F$66,2) -> 11595672
A6: بدلات مجلس الإدارة والحوكمة | B6: 25000 | C6: 1 | D6: 1 | E6: 1 | F6: 1 | G6: 1 | H6: =$B6*C6*12*(1+Assumptions!$B$35)^0*Assumptions!$B$66 -> 193846.15 | I6: =$B6*D6*12*(1+Assumptions!$B$35)^1*Assumptions!$C$66 -> 324000 | J6: =ROUND($B6*E6*12*(1+Assumptions!$B$35)^2*Assumptions!$D$66,2) -> 363000 | K6: =ROUND($B6*F6*12*(1+Assumptions!$B$35)^3*Assumptions!$E$66,2) -> 399300 | L6: =ROUND($B6*G6*12*(1+Assumptions!$B$35)^4*Assumptions!$F$66,2) -> 439230
A7: كهرباء وإنترنت المركز الرئيسي | B7: 20000 | C7: 1 | D7: 1 | E7: 1 | F7: 1 | G7: 1 | H7: =$B7*C7*12*(1+Assumptions!$B$35)^0*Assumptions!$B$66 -> 155076.92 | I7: =$B7*D7*12*(1+Assumptions!$B$35)^1*Assumptions!$C$66 -> 259200 | J7: =ROUND($B7*E7*12*(1+Assumptions!$B$35)^2*Assumptions!$D$66,2) -> 290400 | K7: =ROUND($B7*F7*12*(1+Assumptions!$B$35)^3*Assumptions!$E$66,2) -> 319440 | L7: =ROUND($B7*G7*12*(1+Assumptions!$B$35)^4*Assumptions!$F$66,2) -> 351384
A8: مرافق مكاتب التوقيع وخدمات الأصول | B8: 2500 | C8: 8 | D8: 8 | E8: 8 | F8: 15 | G8: 22 | H8: =$B8*C8*12*(1+Assumptions!$B$35)^0*Assumptions!$B$66 -> 155076.92 | I8: =$B8*D8*12*(1+Assumptions!$B$35)^1*Assumptions!$C$66 -> 259200 | J8: =ROUND($B8*E8*12*(1+Assumptions!$B$35)^2*Assumptions!$D$66,2) -> 290400 | K8: =ROUND($B8*F8*12*(1+Assumptions!$B$35)^3*Assumptions!$E$66,2) -> 598950 | L8: =ROUND($B8*G8*12*(1+Assumptions!$B$35)^4*Assumptions!$F$66,2) -> 966306
A9: مياه ونظافة | B9: 5000 | C9: 1 | D9: 1 | E9: 1 | F9: 1 | G9: 1 | H9: =$B9*C9*12*(1+Assumptions!$B$35)^0*Assumptions!$B$66 -> 38769.231 | I9: =$B9*D9*12*(1+Assumptions!$B$35)^1*Assumptions!$C$66 -> 64800 | J9: =ROUND($B9*E9*12*(1+Assumptions!$B$35)^2*Assumptions!$D$66,2) -> 72600 | K9: =ROUND($B9*F9*12*(1+Assumptions!$B$35)^3*Assumptions!$E$66,2) -> 79860 | L9: =ROUND($B9*G9*12*(1+Assumptions!$B$35)^4*Assumptions!$F$66,2) -> 87846
A10: مواصلات وانتقالات | B10: 10000 | C10: 1 | D10: 1 | E10: 1 | F10: 1 | G10: 1 | H10: =$B10*C10*12*(1+Assumptions!$B$35)^0*Assumptions!$B$66 -> 77538.462 | I10: =$B10*D10*12*(1+Assumptions!$B$35)^1*Assumptions!$C$66 -> 129600 | J10: =ROUND($B10*E10*12*(1+Assumptions!$B$35)^2*Assumptions!$D$66,2) -> 145200 | K10: =ROUND($B10*F10*12*(1+Assumptions!$B$35)^3*Assumptions!$E$66,2) -> 159720 | L10: =ROUND($B10*G10*12*(1+Assumptions!$B$35)^4*Assumptions!$F$66,2) -> 175692
A11: صيانة أجهزة وأنظمة | B11: 15000 | C11: 1 | D11: 1 | E11: 1 | F11: 1 | G11: 1 | H11: =$B11*C11*12*(1+Assumptions!$B$35)^0*Assumptions!$B$66 -> 116307.69 | I11: =$B11*D11*12*(1+Assumptions!$B$35)^1*Assumptions!$C$66 -> 194400 | J11: =ROUND($B11*E11*12*(1+Assumptions!$B$35)^2*Assumptions!$D$66,2) -> 217800 | K11: =ROUND($B11*F11*12*(1+Assumptions!$B$35)^3*Assumptions!$E$66,2) -> 239580 | L11: =ROUND($B11*G11*12*(1+Assumptions!$B$35)^4*Assumptions!$F$66,2) -> 263538
A12: تسويق وتشغيل رقمي | B12: 35000 | C12: 1 | D12: 1 | E12: 1 | F12: 1 | G12: 1 | H12: =$B12*C12*12*(1+Assumptions!$B$35)^0*Assumptions!$B$66 -> 271384.62 | I12: =$B12*D12*12*(1+Assumptions!$B$35)^1*Assumptions!$C$66 -> 453600 | J12: =ROUND($B12*E12*12*(1+Assumptions!$B$35)^2*Assumptions!$D$66,2) -> 508200 | K12: =ROUND($B12*F12*12*(1+Assumptions!$B$35)^3*Assumptions!$E$66,2) -> 559020 | L12: =ROUND($B12*G12*12*(1+Assumptions!$B$35)^4*Assumptions!$F$66,2) -> 614922
A13: رسوم الهيئة وتجديدات رقابية | B13: 50000 | C13: 1 | D13: 1 | E13: 1 | F13: 1 | G13: 1 | H13: =$B13*C13*12*(1+Assumptions!$B$35)^0*Assumptions!$B$66 -> 387692.31 | I13: =$B13*D13*12*(1+Assumptions!$B$35)^1*Assumptions!$C$66 -> 648000 | J13: =ROUND($B13*E13*12*(1+Assumptions!$B$35)^2*Assumptions!$D$66,2) -> 726000 | K13: =ROUND($B13*F13*12*(1+Assumptions!$B$35)^3*Assumptions!$E$66,2) -> 798600 | L13: =ROUND($B13*G13*12*(1+Assumptions!$B$35)^4*Assumptions!$F$66,2) -> 878460
A14: أدوات كتابية ومطبوعات | B14: 20000 | C14: 1 | D14: 1 | E14: 1 | F14: 1 | G14: 1 | H14: =$B14*C14*12*(1+Assumptions!$B$35)^0*Assumptions!$B$66 -> 155076.92 | I14: =$B14*D14*12*(1+Assumptions!$B$35)^1*Assumptions!$C$66 -> 259200 | J14: =ROUND($B14*E14*12*(1+Assumptions!$B$35)^2*Assumptions!$D$66,2) -> 290400 | K14: =ROUND($B14*F14*12*(1+Assumptions!$B$35)^3*Assumptions!$E$66,2) -> 319440 | L14: =ROUND($B14*G14*12*(1+Assumptions!$B$35)^4*Assumptions!$F$66,2) -> 351384
A15: مصروفات قانونية واستشارات | B15: 12000 | C15: 1 | D15: 1 | E15: 1 | F15: 1 | G15: 1 | H15: =$B15*C15*12*(1+Assumptions!$B$35)^0*Assumptions!$B$66 -> 93046.154 | I15: =$B15*D15*12*(1+Assumptions!$B$35)^1*Assumptions!$C$66 -> 155520 | J15: =ROUND($B15*E15*12*(1+Assumptions!$B$35)^2*Assumptions!$D$66,2) -> 174240 | K15: =ROUND($B15*F15*12*(1+Assumptions!$B$35)^3*Assumptions!$E$66,2) -> 191664 | L15: =ROUND($B15*G15*12*(1+Assumptions!$B$35)^4*Assumptions!$F$66,2) -> 210830.4
... A18: خدمة عملاء واتصالات | B18: 10000 | C18: 1 | D18: 1 | E18: 1 | F18: 1 | G18: 1 | H18: =$B18*C18*12*(1+Assumptions!$B$35)^0*Assumptions!$B$66 -> 77538.462 | I18: =$B18*D18*12*(1+Assumptions!$B$35)^1*Assumptions!$C$66 -> 129600 | J18: =ROUND($B18*E18*12*(1+Assumptions!$B$35)^2*Assumptions!$D$66,2) -> 145200 | K18: =ROUND($B18*F18*12*(1+Assumptions!$B$35)^3*Assumptions!$E$66,2) -> 159720 | L18: =ROUND($B18*G18*12*(1+Assumptions!$B$35)^4*Assumptions!$F$66,2) -> 175692
A19: إجمالي المصروفات الإدارية والعمومية | H19: =SUM(H4:H18) -> 4435200 | I19: =SUM(I4:I18) -> 7413120 | J19: =SUM(J4:J18) -> 8305440 | K19: =SUM(K4:K18) -> 12769614 | L19: =SUM(L4:L18) -> 18043568
A20: موازنة G&A المعتمدة للسنتين المقفلتين | H20: 4435200 | I20: 7413120
A21: منهجية المصروفات | B21: Year 1-Year 2: تفاصيل البنود توائم إلى الموازنة السنوية المعتمدة باستخدام معامل مشتق آليا من إجمالي الموازنة. من Year 3: تكلفة الوحدة الشهرية × عدد الوحدات × 12 × الزيادة السنوية، بدون معامل موازنة إضافي.
A22: وظائف المكاتب | B22: التوقيعات، استلام وتسليم الأصل، المعاينات والاستعلامات الميدانية، المتابعة الدورية والاسترداد
A23: مخزن الأصول المستردة | B23: افتراض: مخزن بالقاهرة في أول 3 سنوات بإيجار تقديري 20,000 جنيه شهريا؛ إفصاح فقط وغير مدرج بالمصروفات لحين التعاقد
A24: مصروفات غير مدرجة | B24: غرامات التأخير ليست إيرادا أساسيا، وتأمين الأصل يحمل على العميل/العقد عند السماح والتوثيق

Sheet Originations
A1: Origination Plan by Period and Quarter - 60 Periods
A3: Period | B3: 46388 | C3: 46419 | D3: 46447 | E3: 46478 | F3: 46508 | G3: 46539 | H3: 46569 | I3: 46600 | J3: 46631 | K3: 46661 | L3: 46692 | M3: 46722 | N3: 46753 | O3: 46784 | P3: 46813 | Q3: 46844 | R3: 46874 | S3: 46905 | T3: 46935 | U3: 46966 | V3: 46997 | W3: 47027 | X3: 47058 | Y3: 47088 | Z3: 47119 | AA3: 47150 | AB3: 47178 | AC3: 47209 | AD3: 47239 | AE3: 47270 | AF3: 47300 | AG3: 47331 | AH3: 47362 | AI3: 47392 | AJ3: 47423 | AK3: 47453 | AL3: 47484 | AM3: 47515 | AN3: 47543 | AO3: 47574 | AP3: 47604 | AQ3: 47635 | AR3: 47665 | AS3: 47696 | AT3: 47727 | AU3: 47757 | AV3: 47788 | AW3: 47818 | AX3: 47849 | AY3: 47880 | AZ3: 47908 | BA3: 47939 | BB3: 47969 | BC3: 48000 | BD3: 48030 | BE3: 48061 | BF3: 48092 | BG3: 48122 | BH3: 48153 | BI3: 48183
A4: Plan Year | B4: 2027 | C4: 2027 | D4: 2027 | E4: 2027 | F4: 2027 | G4: 2027 | H4: 2027 | I4: 2027 | J4: 2027 | K4: 2027 | L4: 2027 | M4: 2027 | N4: 2028 | O4: 2028 | P4: 2028 | Q4: 2028 | R4: 2028 | S4: 2028 | T4: 2028 | U4: 2028 | V4: 2028 | W4: 2028 | X4: 2028 | Y4: 2028 | Z4: 2029 | AA4: 2029 | AB4: 2029 | AC4: 2029 | AD4: 2029 | AE4: 2029 | AF4: 2029 | AG4: 2029 | AH4: 2029 | AI4: 2029 | AJ4: 2029 | AK4: 2029 | AL4: 2030 | AM4: 2030 | AN4: 2030 | AO4: 2030 | AP4: 2030 | AQ4: 2030 | AR4: 2030 | AS4: 2030 | AT4: 2030 | AU4: 2030 | AV4: 2030 | AW4: 2030 | AX4: 2031 | AY4: 2031 | AZ4: 2031 | BA4: 2031 | BB4: 2031 | BC4: 2031 | BD4: 2031 | BE4: 2031 | BF4: 2031 | BG4: 2031 | BH4: 2031 | BI4: 2031
A5: Period Sequence | B5: 1 | C5: 2 | D5: 3 | E5: 4 | F5: 5 | G5: 6 | H5: 7 | I5: 8 | J5: 9 | K5: 10 | L5: 11 | M5: 12 | N5: 13 | O5: 14 | P5: 15 | Q5: 16 | R5: 17 | S5: 18 | T5: 19 | U5: 20 | V5: 21 | W5: 22 | X5: 23 | Y5: 24 | Z5: 25 | AA5: 26 | AB5: 27 | AC5: 28 | AD5: 29 | AE5: 30 | AF5: 31 | AG5: 32 | AH5: 33 | AI5: 34 | AJ5: 35 | AK5: 36 | AL5: 37 | AM5: 38 | AN5: 39 | AO5: 40 | AP5: 41 | AQ5: 42 | AR5: 43 | AS5: 44 | AT5: 45 | AU5: 46 | AV5: 47 | AW5: 48 | AX5: 49 | AY5: 50 | AZ5: 51 | BA5: 52 | BB5: 53 | BC5: 54 | BD5: 55 | BE5: 56 | BF5: 57 | BG5: 58 | BH5: 59 | BI5: 60
A6: وزن الشهر داخل السنة | B6: 0 | C6: 0.071428571 | D6: 0.071428571 | E6: 0.082142857 | F6: 0.082142857 | G6: 0.082142857 | H6: 0.096428571 | I6: 0.096428571 | J6: 0.096428571 | K6: 0.10714286 | L6: 0.10714286 | M6: 0.10714286 | N6: 0.066666667 | O6: 0.066666667 | P6: 0.066666667 | Q6: 0.076666667 | R6: 0.076666667 | S6: 0.076666667 | T6: 0.09 | U6: 0.09 | V6: 0.09 | W6: 0.1 | X6: 0.1 | Y6: 0.1 | Z6: 0.066666667 | AA6: 0.066666667 | AB6: 0.066666667 | AC6: 0.076666667 | AD6: 0.076666667 | AE6: 0.076666667 | AF6: 0.09 | AG6: 0.09 | AH6: 0.09 | AI6: 0.1 | AJ6: 0.1 | AK6: 0.1 | AL6: 0.066666667 | AM6: 0.066666667 | AN6: 0.066666667 | AO6: 0.076666667 | AP6: 0.076666667 | AQ6: 0.076666667 | AR6: 0.09 | AS6: 0.09 | AT6: 0.09 | AU6: 0.1 | AV6: 0.1 | AW6: 0.1 | AX6: 0.066666667 | AY6: 0.066666667 | AZ6: 0.066666667 | BA6: 0.076666667 | BB6: 0.076666667 | BC6: 0.076666667 | BD6: 0.09 | BE6: 0.09 | BF6: 0.09 | BG6: 0.1 | BH6: 0.1 | BI6: 0.1
A7: المنح الشهري المخطط | B7: =Assumptions!B$4*B$6 -> 0 | C7: =Assumptions!B$4*C$6 -> 1982142.9 | D7: =Assumptions!B$4*D$6 -> 1982142.9 | E7: =Assumptions!B$4*E$6 -> 2279464.3 | F7: =Assumptions!B$4*F$6 -> 2279464.3 | G7: =Assumptions!B$4*G$6 -> 2279464.3 | H7: =Assumptions!B$4*H$6 -> 2675892.9 | I7: =Assumptions!B$4*I$6 -> 2675892.9 | J7: =Assumptions!B$4*J$6 -> 2675892.9 | K7: =Assumptions!B$4*K$6 -> 2973214.3 | L7: =Assumptions!B$4*L$6 -> 2973214.3 | M7: =Assumptions!B$4*M$6 -> 2973214.3 | N7: =Assumptions!C$4*N$6 -> 35166667 | O7: =Assumptions!C$4*O$6 -> 35166667 | P7: =Assumptions!C$4*P$6 -> 35166667 | Q7: =Assumptions!C$4*Q$6 -> 40441667 | R7: =Assumptions!C$4*R$6 -> 40441667 | S7: =Assumptions!C$4*S$6 -> 40441667 | T7: =Assumptions!C$4*T$6 -> 47475000 | U7: =Assumptions!C$4*U$6 -> 47475000 | V7: =Assumptions!C$4*V$6 -> 47475000 | W7: =Assumptions!C$4*W$6 -> 52750000 | X7: =Assumptions!C$4*X$6 -> 52750000 | Y7: =Assumptions!C$4*Y$6 -> 52750000 | Z7: =Assumptions!D$4*Z$6 -> 46666667 | AA7: =Assumptions!D$4*AA$6 -> 46666667 | AB7: =Assumptions!D$4*AB$6 -> 46666667 | AC7: =Assumptions!D$4*AC$6 -> 53666667 | AD7: =Assumptions!D$4*AD$6 -> 53666667 | AE7: =Assumptions!D$4*AE$6 -> 53666667 | AF7: =Assumptions!D$4*AF$6 -> 63000000 | AG7: =Assumptions!D$4*AG$6 -> 63000000 | AH7: =Assumptions!D$4*AH$6 -> 63000000 | AI7: =Assumptions!D$4*AI$6 -> 70000000 | AJ7: =Assumptions!D$4*AJ$6 -> 70000000 | AK7: =Assumptions!D$4*AK$6 -> 70000000 | AL7: =Assumptions!E$4*AL$6 -> 90000000 | AM7: =Assumptions!E$4*AM$6 -> 90000000 | AN7: =Assumptions!E$4*AN$6 -> 90000000 | AO7: =Assumptions!E$4*AO$6 -> 103500000 | AP7: =Assumptions!E$4*AP$6 -> 103500000 | AQ7: =Assumptions!E$4*AQ$6 -> 103500000 | AR7: =Assumptions!E$4*AR$6 -> 121500000 | AS7: =Assumptions!E$4*AS$6 -> 121500000 | AT7: =Assumptions!E$4*AT$6 -> 121500000 | AU7: =Assumptions!E$4*AU$6 -> 135000000 | AV7: =Assumptions!E$4*AV$6 -> 135000000 | AW7: =Assumptions!E$4*AW$6 -> 135000000 | AX7: =Assumptions!F$4*AX$6 -> 1.6666667e+08 | AY7: =Assumptions!F$4*AY$6 -> 1.6666667e+08 | AZ7: =Assumptions!F$4*AZ$6 -> 1.6666667e+08 | BA7: =Assumptions!F$4*BA$6 -> 1.9166667e+08 | BB7: =Assumptions!F$4*BB$6 -> 1.9166667e+08 | BC7: =Assumptions!F$4*BC$6 -> 1.9166667e+08 | BD7: =Assumptions!F$4*BD$6 -> 225000000 | BE7: =Assumptions!F$4*BE$6 -> 225000000 | BF7: =Assumptions!F$4*BF$6 -> 225000000 | BG7: =Assumptions!F$4*BG$6 -> 250000000 | BH7: =Assumptions!F$4*BH$6 -> 250000000 | BI7: =Assumptions!F$4*BI$6 -> 250000000
A8: المنح المتاح ضمن الخطة التمويلية | B8: =Assumptions!B$5*B$6 -> 0 | C8: =Assumptions!B$5*C$6 -> 1982142.9 | D8: =Assumptions!B$5*D$6 -> 1982142.9 | E8: =Assumptions!B$5*E$6 -> 2279464.3 | F8: =Assumptions!B$5*F$6 -> 2279464.3 | G8: =Assumptions!B$5*G$6 -> 2279464.3 | H8: =Assumptions!B$5*H$6 -> 2675892.9 | I8: =Assumptions!B$5*I$6 -> 2675892.9 | J8: =Assumptions!B$5*J$6 -> 2675892.9 | K8: =Assumptions!B$5*K$6 -> 2973214.3 | L8: =Assumptions!B$5*L$6 -> 2973214.3 | M8: =Assumptions!B$5*M$6 -> 2973214.3 | N8: =Assumptions!C$5*N$6 -> 35166667 | O8: =Assumptions!C$5*O$6 -> 35166667 | P8: =Assumptions!C$5*P$6 -> 35166667 | Q8: =Assumptions!C$5*Q$6 -> 40441667 | R8: =Assumptions!C$5*R$6 -> 40441667 | S8: =Assumptions!C$5*S$6 -> 40441667 | T8: =Assumptions!C$5*T$6 -> 47475000 | U8: =Assumptions!C$5*U$6 -> 47475000 | V8: =Assumptions!C$5*V$6 -> 47475000 | W8: =Assumptions!C$5*W$6 -> 52750000 | X8: =Assumptions!C$5*X$6 -> 52750000 | Y8: =Assumptions!C$5*Y$6 -> 52750000 | Z8: =Assumptions!D$5*Z$6 -> 46666667 | AA8: =Assumptions!D$5*AA$6 -> 46666667 | AB8: =Assumptions!D$5*AB$6 -> 46666667 | AC8: =Assumptions!D$5*AC$6 -> 53666667 | AD8: =Assumptions!D$5*AD$6 -> 53666667 | AE8: =Assumptions!D$5*AE$6 -> 53666667 | AF8: =Assumptions!D$5*AF$6 -> 63000000 | AG8: =Assumptions!D$5*AG$6 -> 63000000 | AH8: =Assumptions!D$5*AH$6 -> 63000000 | AI8: =Assumptions!D$5*AI$6 -> 70000000 | AJ8: =Assumptions!D$5*AJ$6 -> 70000000 | AK8: =Assumptions!D$5*AK$6 -> 70000000 | AL8: =Assumptions!E$5*AL$6 -> 90000000 | AM8: =Assumptions!E$5*AM$6 -> 90000000 | AN8: =Assumptions!E$5*AN$6 -> 90000000 | AO8: =Assumptions!E$5*AO$6 -> 103500000 | AP8: =Assumptions!E$5*AP$6 -> 103500000 | AQ8: =Assumptions!E$5*AQ$6 -> 103500000 | AR8: =Assumptions!E$5*AR$6 -> 121500000 | AS8: =Assumptions!E$5*AS$6 -> 121500000 | AT8: =Assumptions!E$5*AT$6 -> 121500000 | AU8: =Assumptions!E$5*AU$6 -> 135000000 | AV8: =Assumptions!E$5*AV$6 -> 135000000 | AW8: =Assumptions!E$5*AW$6 -> 135000000 | AX8: =Assumptions!F$5*AX$6 -> 1.6666667e+08 | AY8: =Assumptions!F$5*AY$6 -> 1.6666667e+08 | AZ8: =Assumptions!F$5*AZ$6 -> 1.6666667e+08 | BA8: =Assumptions!F$5*BA$6 -> 1.9166667e+08 | BB8: =Assumptions!F$5*BB$6 -> 1.9166667e+08 | BC8: =Assumptions!F$5*BC$6 -> 1.9166667e+08 | BD8: =Assumptions!F$5*BD$6 -> 225000000 | BE8: =Assumptions!F$5*BE$6 -> 225000000 | BF8: =Assumptions!F$5*BF$6 -> 225000000 | BG8: =Assumptions!F$5*BG$6 -> 250000000 | BH8: =Assumptions!F$5*BH$6 -> 250000000 | BI8: =Assumptions!F$5*BI$6 -> 250000000
A9: المنح المستخدم في جداول المحفظة | B9: =Assumptions!B$4*B$6 -> 0 | C9: =Assumptions!B$4*C$6 -> 1982142.9 | D9: =Assumptions!B$4*D$6 -> 1982142.9 | E9: =Assumptions!B$4*E$6 -> 2279464.3 | F9: =Assumptions!B$4*F$6 -> 2279464.3 | G9: =Assumptions!B$4*G$6 -> 2279464.3 | H9: =Assumptions!B$4*H$6 -> 2675892.9 | I9: =Assumptions!B$4*I$6 -> 2675892.9 | J9: =Assumptions!B$4*J$6 -> 2675892.9 | K9: =Assumptions!B$4*K$6 -> 2973214.3 | L9: =Assumptions!B$4*L$6 -> 2973214.3 | M9: =Assumptions!B$4*M$6 -> 2973214.3 | N9: =Assumptions!C$4*N$6 -> 35166667 | O9: =Assumptions!C$4*O$6 -> 35166667 | P9: =Assumptions!C$4*P$6 -> 35166667 | Q9: =Assumptions!C$4*Q$6 -> 40441667 | R9: =Assumptions!C$4*R$6 -> 40441667 | S9: =Assumptions!C$4*S$6 -> 40441667 | T9: =Assumptions!C$4*T$6 -> 47475000 | U9: =Assumptions!C$4*U$6 -> 47475000 | V9: =Assumptions!C$4*V$6 -> 47475000 | W9: =Assumptions!C$4*W$6 -> 52750000 | X9: =Assumptions!C$4*X$6 -> 52750000 | Y9: =Assumptions!C$4*Y$6 -> 52750000 | Z9: =Assumptions!D$4*Z$6 -> 46666667 | AA9: =Assumptions!D$4*AA$6 -> 46666667 | AB9: =Assumptions!D$4*AB$6 -> 46666667 | AC9: =Assumptions!D$4*AC$6 -> 53666667 | AD9: =Assumptions!D$4*AD$6 -> 53666667 | AE9: =Assumptions!D$4*AE$6 -> 53666667 | AF9: =Assumptions!D$4*AF$6 -> 63000000 | AG9: =Assumptions!D$4*AG$6 -> 63000000 | AH9: =Assumptions!D$4*AH$6 -> 63000000 | AI9: =Assumptions!D$4*AI$6 -> 70000000 | AJ9: =Assumptions!D$4*AJ$6 -> 70000000 | AK9: =Assumptions!D$4*AK$6 -> 70000000 | AL9: =Assumptions!E$4*AL$6 -> 90000000 | AM9: =Assumptions!E$4*AM$6 -> 90000000 | AN9: =Assumptions!E$4*AN$6 -> 90000000 | AO9: =Assumptions!E$4*AO$6 -> 103500000 | AP9: =Assumptions!E$4*AP$6 -> 103500000 | AQ9: =Assumptions!E$4*AQ$6 -> 103500000 | AR9: =Assumptions!E$4*AR$6 -> 121500000 | AS9: =Assumptions!E$4*AS$6 -> 121500000 | AT9: =Assumptions!E$4*AT$6 -> 121500000 | AU9: =Assumptions!E$4*AU$6 -> 135000000 | AV9: =Assumptions!E$4*AV$6 -> 135000000 | AW9: =Assumptions!E$4*AW$6 -> 135000000 | AX9: =Assumptions!F$4*AX$6 -> 1.6666667e+08 | AY9: =Assumptions!F$4*AY$6 -> 1.6666667e+08 | AZ9: =Assumptions!F$4*AZ$6 -> 1.6666667e+08 | BA9: =Assumptions!F$4*BA$6 -> 1.9166667e+08 | BB9: =Assumptions!F$4*BB$6 -> 1.9166667e+08 | BC9: =Assumptions!F$4*BC$6 -> 1.9166667e+08 | BD9: =Assumptions!F$4*BD$6 -> 225000000 | BE9: =Assumptions!F$4*BE$6 -> 225000000 | BF9: =Assumptions!F$4*BF$6 -> 225000000 | BG9: =Assumptions!F$4*BG$6 -> 250000000 | BH9: =Assumptions!F$4*BH$6 -> 250000000 | BI9: =Assumptions!F$4*BI$6 -> 250000000
A10: هامش تمويلي غير مستخدم | B10: =0 -> 0 | C10: =0 -> 0 | D10: =0 -> 0 | E10: =0 -> 0 | F10: =0 -> 0 | G10: =0 -> 0 | H10: =0 -> 0 | I10: =0 -> 0 | ... BI10: =0 -> 0
A11: عدد العقود | B11: =ROUND(Assumptions!B77*B$6,0) -> 0 | C11: =ROUND(Assumptions!B77*C$6,0) -> 13 | D11: =ROUND(Assumptions!B77*D$6,0) -> 13 | E11: =ROUND(Assumptions!B77*E$6,0) -> 15 | F11: =ROUND(Assumptions!B77*F$6,0) -> 15 | G11: =ROUND(Assumptions!B77*G$6,0) -> 15 | H11: =ROUND(Assumptions!B77*H$6,0) -> 18 | I11: =ROUND(Assumptions!B77*I$6,0) -> 18 | J11: =ROUND(Assumptions!B77*J$6,0) -> 18 | K11: =ROUND(Assumptions!B77*K$6,0) -> 20 | L11: =ROUND(Assumptions!B77*L$6,0) -> 20 | M11: =Assumptions!B77-SUM(B11:L11) -> 20 | N11: =ROUND(Assumptions!C77*N$6,0) -> 111 | O11: =ROUND(Assumptions!C77*O$6,0) -> 111 | P11: =ROUND(Assumptions!C77*P$6,0) -> 111 | Q11: =ROUND(Assumptions!C77*Q$6,0) -> 128 | R11: =ROUND(Assumptions!C77*R$6,0) -> 128 | S11: =ROUND(Assumptions!C77*S$6,0) -> 128 | T11: =ROUND(Assumptions!C77*T$6,0) -> 150 | U11: =ROUND(Assumptions!C77*U$6,0) -> 150 | V11: =ROUND(Assumptions!C77*V$6,0) -> 150 | W11: =ROUND(Assumptions!C77*W$6,0) -> 167 | X11: =ROUND(Assumptions!C77*X$6,0) -> 167 | Y11: =Assumptions!C77-SUM(N11:X11) -> 169 | Z11: =ROUND(Assumptions!D77*Z$6,0) -> 53 | AA11: =ROUND(Assumptions!D77*AA$6,0) -> 53 | AB11: =ROUND(Assumptions!D77*AB$6,0) -> 53 | AC11: =ROUND(Assumptions!D77*AC$6,0) -> 60 | AD11: =ROUND(Assumptions!D77*AD$6,0) -> 60 | AE11: =ROUND(Assumptions!D77*AE$6,0) -> 60 | AF11: =ROUND(Assumptions!D77*AF$6,0) -> 71 | AG11: =ROUND(Assumptions!D77*AG$6,0) -> 71 | AH11: =ROUND(Assumptions!D77*AH$6,0) -> 71 | AI11: =ROUND(Assumptions!D77*AI$6,0) -> 79 | AJ11: =ROUND(Assumptions!D77*AJ$6,0) -> 79 | AK11: =Assumptions!D77-SUM(Z11:AJ11) -> 78 | AL11: =ROUND(Assumptions!E77*AL$6,0) -> 82 | AM11: =ROUND(Assumptions!E77*AM$6,0) -> 82 | AN11: =ROUND(Assumptions!E77*AN$6,0) -> 82 | AO11: =ROUND(Assumptions!E77*AO$6,0) -> 94 | AP11: =ROUND(Assumptions!E77*AP$6,0) -> 94 | AQ11: =ROUND(Assumptions!E77*AQ$6,0) -> 94 | AR11: =ROUND(Assumptions!E77*AR$6,0) -> 110 | AS11: =ROUND(Assumptions!E77*AS$6,0) -> 110 | AT11: =ROUND(Assumptions!E77*AT$6,0) -> 110 | AU11: =ROUND(Assumptions!E77*AU$6,0) -> 123 | AV11: =ROUND(Assumptions!E77*AV$6,0) -> 123 | AW11: =Assumptions!E77-SUM(AL11:AV11) -> 123 | AX11: =ROUND(Assumptions!F77*AX$6,0) -> 123 | AY11: =ROUND(Assumptions!F77*AY$6,0) -> 123 | AZ11: =ROUND(Assumptions!F77*AZ$6,0) -> 123 | BA11: =ROUND(Assumptions!F77*BA$6,0) -> 142 | BB11: =ROUND(Assumptions!F77*BB$6,0) -> 142 | BC11: =ROUND(Assumptions!F77*BC$6,0) -> 142 | BD11: =ROUND(Assumptions!F77*BD$6,0) -> 167 | BE11: =ROUND(Assumptions!F77*BE$6,0) -> 167 | BF11: =ROUND(Assumptions!F77*BF$6,0) -> 167 | BG11: =ROUND(Assumptions!F77*BG$6,0) -> 185 | BH11: =ROUND(Assumptions!F77*BH$6,0) -> 185 | BI11: =Assumptions!F77-SUM(AX11:BH11) -> 186
A12: Quarterly Origination Summary
A13: Quarter | B13: Year 1 | C13: Year 2 | D13: Year 3 | E13: Year 4 | F13: Year 5
A14: الربع الأول (Q1) | B14: =SUM(B7:D7) -> 3964285.7 | C14: =SUM(N7:P7) -> 105500000 | D14: =SUM(Z7:AB7) -> 140000000 | E14: =SUM(AL7:AN7) -> 270000000 | F14: =SUM(AX7:AZ7) -> 500000000
A15: الربع الثاني (Q2) | B15: =SUM(E7:G7) -> 6838392.9 | C15: =SUM(Q7:S7) -> 121325000 | D15: =SUM(AC7:AE7) -> 161000000 | E15: =SUM(AO7:AQ7) -> 310500000 | F15: =SUM(BA7:BC7) -> 575000000
A16: الربع الثالث (Q3) | B16: =SUM(H7:J7) -> 8027678.6 | C16: =SUM(T7:V7) -> 142425000 | D16: =SUM(AF7:AH7) -> 189000000 | E16: =SUM(AR7:AT7) -> 364500000 | F16: =SUM(BD7:BF7) -> 675000000
A17: الربع الرابع (Q4) | B17: =SUM(K7:M7) -> 8919642.9 | C17: =SUM(W7:Y7) -> 158250000 | D17: =SUM(AI7:AK7) -> 210000000 | E17: =SUM(AU7:AW7) -> 405000000 | F17: =SUM(BG7:BI7) -> 750000000
A18: الإجمالي | B18: =SUM(B14:B17) -> 27750000 | C18: =SUM(C14:C17) -> 527500000 | D18: =SUM(D14:D17) -> 700000000 | E18: =SUM(E14:E17) -> 1350000000 | F18: =SUM(F14:F17) -> 2500000000
A19: Year 4 | B19: =SUM(AL9:AN9)/1000000 -> 270 | C19: =SUM(AO9:AQ9)/1000000 -> 310.5 | D19: =SUM(AR9:AT9)/1000000 -> 364.5 | E19: =SUM(AU9:AW9)/1000000 -> 405 | F19: =SUM(B19:E19) -> 1350
A20: Year 5 | B20: =SUM(AX9:AZ9)/1000000 -> 500 | C20: =SUM(BA9:BC9)/1000000 -> 575 | D20: =SUM(BD9:BF9)/1000000 -> 675 | E20: =SUM(BG9:BI9)/1000000 -> 750 | F20: =SUM(B20:E20) -> 2500

Sheet Cohort Principal
A1: جدول تطور أصل المحفظة
A3: البند | B3: Year 1 | C3: Year 2 | D3: Year 3 | E3: Year 4 | F3: Year 5
A4: رصيد أول السنة | B4: =0 -> 0 | C4: =B7 -> 20672304 | D4: =C7 -> 4.5260222e+08 | E4: =D7 -> 8.6656133e+08 | F4: =E7 -> 1.6674368e+09
A5: الأصل الممول من المنح | B5: =Assumptions!B76*(1-Assumptions!$B$25) -> 23587500 | C5: =Assumptions!C76*(1-Assumptions!$B$25) -> 448375000 | D5: =Assumptions!D76*(1-Assumptions!$B$25) -> 595000000 | E5: =Assumptions!E76*(1-Assumptions!$B$25) -> 1147500000 | F5: =Assumptions!F76*(1-Assumptions!$B$25) -> 2125000000
A6: تحصيل/استنفاد أصل المحفظة | B6: =B4+B5-Assumptions!B79 -> 2915195.9 | C6: =C4+C5-Assumptions!C79 -> 16445084 | D6: =D4+D5-Assumptions!D79 -> 1.8104089e+08 | E6: =E4+E5-Assumptions!E79 -> 3.4662453e+08 | F6: =F4+F5-Assumptions!F79 -> 6.6697472e+08
A7: رصيد آخر السنة | B7: =B4+B5-B6 -> 20672304 | C7: =C4+C5-C6 -> 4.5260222e+08 | D7: =D4+D5-D6 -> 8.6656133e+08 | E7: =E4+E5-E6 -> 1.6674368e+09 | F7: =F4+F5-F6 -> 3.1254621e+09
A8: اختبار الربط | B8: =B7-'Balance Sheet'!B6 -> 0 | C8: =C7-'Balance Sheet'!C6 -> 0 | D8: =D7-'Balance Sheet'!D6 -> 0 | E8: =E7-'Balance Sheet'!E6 -> 0 | F8: =F7-'Balance Sheet'!F6 -> 0

Sheet Cohort Interest
A1: جدول احتساب عوائد التأجير
A3: البند | B3: Year 1 | C3: Year 2 | D3: Year 3 | E3: Year 4 | F3: Year 5
A4: رصيد أول السنة | B4: =0 -> 0 | C4: ='Balance Sheet'!B6 -> 20672304 | D4: ='Balance Sheet'!C6 -> 4.5260222e+08 | E4: ='Balance Sheet'!D6 -> 8.6656133e+08 | F4: ='Balance Sheet'!E6 -> 1.6674368e+09
A5: رصيد آخر السنة | B5: ='Balance Sheet'!B6 -> 20672304 | C5: ='Balance Sheet'!C6 -> 4.5260222e+08 | D5: ='Balance Sheet'!D6 -> 8.6656133e+08 | E5: ='Balance Sheet'!E6 -> 1.6674368e+09 | F5: ='Balance Sheet'!F6 -> 3.1254621e+09
A6: متوسط المحفظة | B6: =AVERAGE(B4,B5) -> 10336152 | C6: =AVERAGE(C4,C5) -> 2.3663726e+08 | D6: =AVERAGE(D4,D5) -> 6.5958178e+08 | E6: =AVERAGE(E4,E5) -> 1.2669991e+09 | F6: =AVERAGE(F4,F5) -> 2.3964494e+09
A7: العائد السنوي | B7: =Assumptions!B6 -> 0.34 | C7: =Assumptions!C6 -> 0.32 | D7: =Assumptions!D6 -> 0.3 | E7: =Assumptions!E6 -> 0.28 | F7: =Assumptions!F6 -> 0.26
A8: عوائد التأجير | B8: 3538848 | C8: 45873640 | D8: =D6*D7 -> 1.9787453e+08 | E8: =E6*E7 -> 3.5475974e+08 | F8: =F6*F7 -> 6.2307685e+08
A9: منهجية الاحتساب | B9: مدخل خطة Year 1 المعتمدة - لا يوجد جدول EIR/عقود شهري مستقل | C9: مدخل خطة Year 2 المعتمدة - لا يوجد جدول EIR/عقود شهري مستقل | D9: متوسط المحفظة × العائد | E9: متوسط المحفظة × العائد | F9: متوسط المحفظة × العائد
A10: العائد الضمني على متوسط المحفظة | B10: =IFERROR(B8/B6,0) -> 0.34237576 | C10: =IFERROR(C8/C6,0) -> 0.19385637 | D10: =IFERROR(D8/D6,0) -> 0.3 | E10: =IFERROR(E8/E6,0) -> 0.28 | F10: =IFERROR(F8/F6,0) -> 0.26

Sheet Cohort Fees
A1: جدول رسوم الخدمات
A3: البند | B3: Year 1 | C3: Year 2 | D3: Year 3 | E3: Year 4 | F3: Year 5
A4: المنح السنوي | B4: =Assumptions!B76 -> 27750000 | C4: =Assumptions!C76 -> 527500000 | D4: =Assumptions!D76 -> 700000000 | E4: =Assumptions!E76 -> 1350000000 | F4: =Assumptions!F76 -> 2500000000
A5: نسبة الرسوم | B5: =Assumptions!B26 -> 0.05 | C5: =Assumptions!C26 -> 0.07 | D5: =Assumptions!D26 -> 0.06 | E5: =Assumptions!E26 -> 0.06 | F5: =Assumptions!F26 -> 0.06
A6: إجمالي الرسوم المحصلة | B6: =B4*B5 -> 1387500 | C6: =C4*C5 -> 36925000 | D6: =D4*D5 -> 42000000 | E6: =E4*E5 -> 81000000 | F6: =F4*F5 -> 150000000
A7: إيرادات الرسوم الإدارية المعتمدة - خطة الإدارة | B7: =Assumptions!B81 -> 1387500 | C7: =Assumptions!C81 -> 36925000 | D7: =Assumptions!D81 -> 42000000 | E7: =Assumptions!E81 -> 81000000 | F7: =Assumptions!F81 -> 150000000
A8: دعم تشغيلي / إيرادات خدمات مساندة أخرى | B8: ='Income Statement'!B13 -> 3118262.4 | C8: ='Income Statement'!C13 -> 0 | D8: ='Income Statement'!D13 -> 5600000 | E8: ='Income Statement'!E13 -> 10800000 | F8: ='Income Statement'!F13 -> 20000000

Sheet Monthly Model
A1: Liquidity and Funding Model - 60 Planning Periods
A3: Period | B3: 46388 | C3: 46419 | D3: 46447 | E3: 46478 | F3: 46508 | G3: 46539 | H3: 46569 | I3: 46600 | J3: 46631 | K3: 46661 | L3: 46692 | M3: 46722 | N3: 46753 | O3: 46784 | P3: 46813 | Q3: 46844 | R3: 46874 | S3: 46905 | T3: 46935 | U3: 46966 | V3: 46997 | W3: 47027 | X3: 47058 | Y3: 47088 | Z3: 47119 | AA3: 47150 | AB3: 47178 | AC3: 47209 | AD3: 47239 | AE3: 47270 | AF3: 47300 | AG3: 47331 | AH3: 47362 | AI3: 47392 | AJ3: 47423 | AK3: 47453 | AL3: 47484 | AM3: 47515 | AN3: 47543 | AO3: 47574 | AP3: 47604 | AQ3: 47635 | AR3: 47665 | AS3: 47696 | AT3: 47727 | AU3: 47757 | AV3: 47788 | AW3: 47818 | AX3: 47849 | AY3: 47880 | AZ3: 47908 | BA3: 47939 | BB3: 47969 | BC3: 48000 | BD3: 48030 | BE3: 48061 | BF3: 48092 | BG3: 48122 | BH3: 48153 | BI3: 48183
A4: Plan Year | B4: 2027 | C4: 2027 | D4: 2027 | E4: 2027 | F4: 2027 | G4: 2027 | H4: 2027 | I4: 2027 | J4: 2027 | K4: 2027 | L4: 2027 | M4: 2027 | N4: 2028 | O4: 2028 | P4: 2028 | Q4: 2028 | R4: 2028 | S4: 2028 | T4: 2028 | U4: 2028 | V4: 2028 | W4: 2028 | X4: 2028 | Y4: 2028 | Z4: 2029 | AA4: 2029 | AB4: 2029 | AC4: 2029 | AD4: 2029 | AE4: 2029 | AF4: 2029 | AG4: 2029 | AH4: 2029 | AI4: 2029 | AJ4: 2029 | AK4: 2029 | AL4: 2030 | AM4: 2030 | AN4: 2030 | AO4: 2030 | AP4: 2030 | AQ4: 2030 | AR4: 2030 | AS4: 2030 | AT4: 2030 | AU4: 2030 | AV4: 2030 | AW4: 2030 | AX4: 2031 | AY4: 2031 | AZ4: 2031 | BA4: 2031 | BB4: 2031 | BC4: 2031 | BD4: 2031 | BE4: 2031 | BF4: 2031 | BG4: 2031 | BH4: 2031 | BI4: 2031
A5: Period Sequence | B5: 1 | C5: 2 | D5: 3 | E5: 4 | F5: 5 | G5: 6 | H5: 7 | I5: 8 | J5: 9 | K5: 10 | L5: 11 | M5: 12 | N5: 13 | O5: 14 | P5: 15 | Q5: 16 | R5: 17 | S5: 18 | T5: 19 | U5: 20 | V5: 21 | W5: 22 | X5: 23 | Y5: 24 | Z5: 25 | AA5: 26 | AB5: 27 | AC5: 28 | AD5: 29 | AE5: 30 | AF5: 31 | AG5: 32 | AH5: 33 | AI5: 34 | AJ5: 35 | AK5: 36 | AL5: 37 | AM5: 38 | AN5: 39 | AO5: 40 | AP5: 41 | AQ5: 42 | AR5: 43 | AS5: 44 | AT5: 45 | AU5: 46 | AV5: 47 | AW5: 48 | AX5: 49 | AY5: 50 | AZ5: 51 | BA5: 52 | BB5: 53 | BC5: 54 | BD5: 55 | BE5: 56 | BF5: 57 | BG5: 58 | BH5: 59 | BI5: 60
A6: وزن الشهر | B6: =Originations!B6 -> 0 | C6: =Originations!C6 -> 0.071428571 | D6: =Originations!D6 -> 0.071428571 | E6: =Originations!E6 -> 0.082142857 | F6: =Originations!F6 -> 0.082142857 | G6: =Originations!G6 -> 0.082142857 | H6: =Originations!H6 -> 0.096428571 | I6: =Originations!I6 -> 0.096428571 | ... BI6: =Originations!BI6 -> 0.1
A8: المنح المخطط | B8: =Originations!B7 -> 0 | C8: =Originations!C7 -> 1982142.9 | D8: =Originations!D7 -> 1982142.9 | E8: =Originations!E7 -> 2279464.3 | F8: =Originations!F7 -> 2279464.3 | G8: =Originations!G7 -> 2279464.3 | H8: =Originations!H7 -> 2675892.9 | I8: =Originations!I7 -> 2675892.9 | ... BI8: =Originations!BI7 -> 250000000
A10: صافي الربح | B10: ='Cash Flow'!B5*B6 -> 0 | C10: ='Cash Flow'!B5*C6 -> -583347.91 | D10: ='Cash Flow'!B5*D6 -> -583347.91 | E10: ='Cash Flow'!B5*E6 -> -670850.1 | F10: ='Cash Flow'!B5*F6 -> -670850.1 | G10: ='Cash Flow'!B5*G6 -> -670850.1 | H10: ='Cash Flow'!B5*H6 -> -787519.68 | I10: ='Cash Flow'!B5*I6 -> -787519.68 | J10: ='Cash Flow'!B5*J6 -> -787519.68 | K10: ='Cash Flow'!B5*K6 -> -875021.87 | L10: ='Cash Flow'!B5*L6 -> -875021.87 | M10: ='Cash Flow'!B5*M6 -> -875021.87 | N10: ='Cash Flow'!C5*N6 -> 616907.74 | O10: ='Cash Flow'!C5*O6 -> 616907.74 | P10: ='Cash Flow'!C5*P6 -> 616907.74 | Q10: ='Cash Flow'!C5*Q6 -> 709443.9 | R10: ='Cash Flow'!C5*R6 -> 709443.9 | S10: ='Cash Flow'!C5*S6 -> 709443.9 | T10: ='Cash Flow'!C5*T6 -> 832825.45 | U10: ='Cash Flow'!C5*U6 -> 832825.45 | V10: ='Cash Flow'!C5*V6 -> 832825.45 | W10: ='Cash Flow'!C5*W6 -> 925361.61 | X10: ='Cash Flow'!C5*X6 -> 925361.61 | Y10: ='Cash Flow'!C5*Y6 -> 925361.61 | Z10: ='Cash Flow'!D5*Z6 -> 5116754.1 | AA10: ='Cash Flow'!D5*AA6 -> 5116754.1 | AB10: ='Cash Flow'!D5*AB6 -> 5116754.1 | AC10: ='Cash Flow'!D5*AC6 -> 5884267.2 | AD10: ='Cash Flow'!D5*AD6 -> 5884267.2 | AE10: ='Cash Flow'!D5*AE6 -> 5884267.2 | AF10: ='Cash Flow'!D5*AF6 -> 6907618 | AG10: ='Cash Flow'!D5*AG6 -> 6907618 | AH10: ='Cash Flow'!D5*AH6 -> 6907618 | AI10: ='Cash Flow'!D5*AI6 -> 7675131.2 | AJ10: ='Cash Flow'!D5*AJ6 -> 7675131.2 | AK10: ='Cash Flow'!D5*AK6 -> 7675131.2 | AL10: ='Cash Flow'!E5*AL6 -> 10662722 | AM10: ='Cash Flow'!E5*AM6 -> 10662722 | AN10: ='Cash Flow'!E5*AN6 -> 10662722 | AO10: ='Cash Flow'!E5*AO6 -> 12262131 | AP10: ='Cash Flow'!E5*AP6 -> 12262131 | AQ10: ='Cash Flow'!E5*AQ6 -> 12262131 | AR10: ='Cash Flow'!E5*AR6 -> 14394675 | AS10: ='Cash Flow'!E5*AS6 -> 14394675 | AT10: ='Cash Flow'!E5*AT6 -> 14394675 | AU10: ='Cash Flow'!E5*AU6 -> 15994083 | AV10: ='Cash Flow'!E5*AV6 -> 15994083 | AW10: ='Cash Flow'!E5*AW6 -> 15994083 | AX10: ='Cash Flow'!F5*AX6 -> 19317332 | AY10: ='Cash Flow'!F5*AY6 -> 19317332 | AZ10: ='Cash Flow'!F5*AZ6 -> 19317332 | BA10: ='Cash Flow'!F5*BA6 -> 22214932 | BB10: ='Cash Flow'!F5*BB6 -> 22214932 | BC10: ='Cash Flow'!F5*BC6 -> 22214932 | BD10: ='Cash Flow'!F5*BD6 -> 26078398 | BE10: ='Cash Flow'!F5*BE6 -> 26078398 | BF10: ='Cash Flow'!F5*BF6 -> 26078398 | BG10: ='Cash Flow'!F5*BG6 -> 28975998 | BH10: ='Cash Flow'!F5*BH6 -> 28975998 | BI10: ='Cash Flow'!F5*BI6 -> 28975998
A11: الإهلاك والاستهلاك (D&A) | B11: ='Cash Flow'!B6*B6 -> 0 | C11: ='Cash Flow'!B6*C6 -> 0 | D11: ='Cash Flow'!B6*D6 -> 0 | E11: ='Cash Flow'!B6*E6 -> 0 | F11: ='Cash Flow'!B6*F6 -> 0 | G11: ='Cash Flow'!B6*G6 -> 0 | H11: ='Cash Flow'!B6*H6 -> 0 | I11: ='Cash Flow'!B6*I6 -> 0 | J11: ='Cash Flow'!B6*J6 -> 0 | K11: ='Cash Flow'!B6*K6 -> 0 | L11: ='Cash Flow'!B6*L6 -> 0 | M11: ='Cash Flow'!B6*M6 -> 0 | N11: ='Cash Flow'!C6*N6 -> 0 | O11: ='Cash Flow'!C6*O6 -> 0 | P11: ='Cash Flow'!C6*P6 -> 0 | Q11: ='Cash Flow'!C6*Q6 -> 0 | R11: ='Cash Flow'!C6*R6 -> 0 | S11: ='Cash Flow'!C6*S6 -> 0 | T11: ='Cash Flow'!C6*T6 -> 0 | U11: ='Cash Flow'!C6*U6 -> 0 | V11: ='Cash Flow'!C6*V6 -> 0 | W11: ='Cash Flow'!C6*W6 -> 0 | X11: ='Cash Flow'!C6*X6 -> 0 | Y11: ='Cash Flow'!C6*Y6 -> 0 | Z11: ='Cash Flow'!D6*Z6 -> 66666.667 | AA11: ='Cash Flow'!D6*AA6 -> 66666.667 | AB11: ='Cash Flow'!D6*AB6 -> 66666.667 | AC11: ='Cash Flow'!D6*AC6 -> 76666.667 | AD11: ='Cash Flow'!D6*AD6 -> 76666.667 | AE11: ='Cash Flow'!D6*AE6 -> 76666.667 | AF11: ='Cash Flow'!D6*AF6 -> 90000 | AG11: ='Cash Flow'!D6*AG6 -> 90000 | AH11: ='Cash Flow'!D6*AH6 -> 90000 | AI11: ='Cash Flow'!D6*AI6 -> 100000 | AJ11: ='Cash Flow'!D6*AJ6 -> 100000 | AK11: ='Cash Flow'!D6*AK6 -> 100000 | AL11: ='Cash Flow'!E6*AL6 -> 100000 | AM11: ='Cash Flow'!E6*AM6 -> 100000 | AN11: ='Cash Flow'!E6*AN6 -> 100000 | AO11: ='Cash Flow'!E6*AO6 -> 115000 | AP11: ='Cash Flow'!E6*AP6 -> 115000 | AQ11: ='Cash Flow'!E6*AQ6 -> 115000 | AR11: ='Cash Flow'!E6*AR6 -> 135000 | AS11: ='Cash Flow'!E6*AS6 -> 135000 | AT11: ='Cash Flow'!E6*AT6 -> 135000 | AU11: ='Cash Flow'!E6*AU6 -> 150000 | AV11: ='Cash Flow'!E6*AV6 -> 150000 | AW11: ='Cash Flow'!E6*AW6 -> 150000 | AX11: ='Cash Flow'!F6*AX6 -> 133333.33 | AY11: ='Cash Flow'!F6*AY6 -> 133333.33 | AZ11: ='Cash Flow'!F6*AZ6 -> 133333.33 | BA11: ='Cash Flow'!F6*BA6 -> 153333.33 | BB11: ='Cash Flow'!F6*BB6 -> 153333.33 | BC11: ='Cash Flow'!F6*BC6 -> 153333.33 | BD11: ='Cash Flow'!F6*BD6 -> 180000 | BE11: ='Cash Flow'!F6*BE6 -> 180000 | BF11: ='Cash Flow'!F6*BF6 -> 180000 | BG11: ='Cash Flow'!F6*BG6 -> 200000 | BH11: ='Cash Flow'!F6*BH6 -> 200000 | BI11: ='Cash Flow'!F6*BI6 -> 200000
